[2025-10-23T16:48:45.009+0000] {taskinstance.py:1159} INFO - Dependencies all met for dep_context=non-requeueable deps ti=<TaskInstance: ckan_data_etl.load scheduled__2024-09-22T00:00:00+00:00 [queued]>
[2025-10-23T16:48:45.040+0000] {taskinstance.py:1159} INFO - Dependencies all met for dep_context=requeueable deps ti=<TaskInstance: ckan_data_etl.load scheduled__2024-09-22T00:00:00+00:00 [queued]>
[2025-10-23T16:48:45.044+0000] {taskinstance.py:1361} INFO - Starting attempt 1 of 2
[2025-10-23T16:48:45.103+0000] {taskinstance.py:1382} INFO - Executing <Task(PythonOperator): load> on 2024-09-22 00:00:00+00:00
[2025-10-23T16:48:45.127+0000] {standard_task_runner.py:57} INFO - Started process 490 to run task
[2025-10-23T16:48:45.144+0000] {standard_task_runner.py:84} INFO - Running: ['***', 'tasks', 'run', 'ckan_data_etl', 'load', 'scheduled__2024-09-22T00:00:00+00:00', '--job-id', '607', '--raw', '--subdir', 'DAGS_FOLDER/crypto_etl_dag.py', '--cfg-path', '/tmp/tmpcxzmrjke']
[2025-10-23T16:48:45.148+0000] {standard_task_runner.py:85} INFO - Job 607: Subtask load
[2025-10-23T16:48:45.329+0000] {task_command.py:416} INFO - Running <TaskInstance: ckan_data_etl.load scheduled__2024-09-22T00:00:00+00:00 [running]> on host 056dd0d0c4ba
[2025-10-23T16:48:45.528+0000] {taskinstance.py:1662} INFO - Exporting env vars: AIRFLOW_CTX_DAG_OWNER='***' AIRFLOW_CTX_DAG_ID='ckan_data_etl' AIRFLOW_CTX_TASK_ID='load' AIRFLOW_CTX_EXECUTION_DATE='2024-09-22T00:00:00+00:00' AIRFLOW_CTX_TRY_NUMBER='1' AIRFLOW_CTX_DAG_RUN_ID='scheduled__2024-09-22T00:00:00+00:00'
[2025-10-23T16:48:45.552+0000] {taskinstance.py:1937} ERROR - Task failed with exception
Traceback (most recent call last):
  File "/home/airflow/.local/lib/python3.8/site-packages/airflow/operators/python.py", line 192, in execute
    return_value = self.execute_callable()
  File "/home/airflow/.local/lib/python3.8/site-packages/airflow/operators/python.py", line 209, in execute_callable
    return self.python_callable(*self.op_args, **self.op_kwargs)
  File "/opt/airflow/dags/crypto_etl_dag.py", line 37, in load_to_db
    df = pd.read_csv(data_path)
  File "/home/airflow/.local/lib/python3.8/site-packages/pandas/io/parsers/readers.py", line 912, in read_csv
    return _read(filepath_or_buffer, kwds)
  File "/home/airflow/.local/lib/python3.8/site-packages/pandas/io/parsers/readers.py", line 577, in _read
    parser = TextFileReader(filepath_or_buffer, **kwds)
  File "/home/airflow/.local/lib/python3.8/site-packages/pandas/io/parsers/readers.py", line 1407, in __init__
    self._engine = self._make_engine(f, self.engine)
  File "/home/airflow/.local/lib/python3.8/site-packages/pandas/io/parsers/readers.py", line 1679, in _make_engine
    return mapping[engine](f, **self.options)
  File "/home/airflow/.local/lib/python3.8/site-packages/pandas/io/parsers/c_parser_wrapper.py", line 93, in __init__
    self._reader = parsers.TextReader(src, **kwds)
  File "pandas/_libs/parsers.pyx", line 557, in pandas._libs.parsers.TextReader.__cinit__
pandas.errors.EmptyDataError: No columns to parse from file
[2025-10-23T16:48:45.574+0000] {taskinstance.py:1400} INFO - Marking task as UP_FOR_RETRY. dag_id=ckan_data_etl, task_id=load, execution_date=20240922T000000, start_date=20251023T164845, end_date=20251023T164845
[2025-10-23T16:48:45.595+0000] {standard_task_runner.py:104} ERROR - Failed to execute job 607 for task load (No columns to parse from file; 490)
[2025-10-23T16:48:45.652+0000] {local_task_job_runner.py:228} INFO - Task exited with return code 1
[2025-10-23T16:48:45.711+0000] {taskinstance.py:2778} INFO - 0 downstream tasks scheduled from follow-on schedule check
