[2025-10-23T16:59:11.674+0000] {taskinstance.py:1159} INFO - Dependencies all met for dep_context=non-requeueable deps ti=<TaskInstance: ckan_data_etl.load scheduled__2024-10-05T00:00:00+00:00 [queued]>
[2025-10-23T16:59:11.709+0000] {taskinstance.py:1159} INFO - Dependencies all met for dep_context=requeueable deps ti=<TaskInstance: ckan_data_etl.load scheduled__2024-10-05T00:00:00+00:00 [queued]>
[2025-10-23T16:59:11.710+0000] {taskinstance.py:1361} INFO - Starting attempt 2 of 2
[2025-10-23T16:59:11.750+0000] {taskinstance.py:1382} INFO - Executing <Task(PythonOperator): load> on 2024-10-05 00:00:00+00:00
[2025-10-23T16:59:11.763+0000] {standard_task_runner.py:57} INFO - Started process 863 to run task
[2025-10-23T16:59:11.785+0000] {standard_task_runner.py:84} INFO - Running: ['***', 'tasks', 'run', 'ckan_data_etl', 'load', 'scheduled__2024-10-05T00:00:00+00:00', '--job-id', '678', '--raw', '--subdir', 'DAGS_FOLDER/crypto_etl_dag.py', '--cfg-path', '/tmp/tmpq_y8g33a']
[2025-10-23T16:59:11.788+0000] {standard_task_runner.py:85} INFO - Job 678: Subtask load
[2025-10-23T16:59:11.971+0000] {task_command.py:416} INFO - Running <TaskInstance: ckan_data_etl.load scheduled__2024-10-05T00:00:00+00:00 [running]> on host 056dd0d0c4ba
[2025-10-23T16:59:12.139+0000] {taskinstance.py:1662} INFO - Exporting env vars: AIRFLOW_CTX_DAG_OWNER='***' AIRFLOW_CTX_DAG_ID='ckan_data_etl' AIRFLOW_CTX_TASK_ID='load' AIRFLOW_CTX_EXECUTION_DATE='2024-10-05T00:00:00+00:00' AIRFLOW_CTX_TRY_NUMBER='2' AIRFLOW_CTX_DAG_RUN_ID='scheduled__2024-10-05T00:00:00+00:00'
[2025-10-23T16:59:12.161+0000] {taskinstance.py:1937} ERROR - Task failed with exception
Traceback (most recent call last):
  File "/home/airflow/.local/lib/python3.8/site-packages/airflow/operators/python.py", line 192, in execute
    return_value = self.execute_callable()
  File "/home/airflow/.local/lib/python3.8/site-packages/airflow/operators/python.py", line 209, in execute_callable
    return self.python_callable(*self.op_args, **self.op_kwargs)
  File "/opt/airflow/dags/crypto_etl_dag.py", line 41, in load_to_db
    df = pd.read_csv(data_path)
  File "/home/airflow/.local/lib/python3.8/site-packages/pandas/io/parsers/readers.py", line 912, in read_csv
    return _read(filepath_or_buffer, kwds)
  File "/home/airflow/.local/lib/python3.8/site-packages/pandas/io/parsers/readers.py", line 577, in _read
    parser = TextFileReader(filepath_or_buffer, **kwds)
  File "/home/airflow/.local/lib/python3.8/site-packages/pandas/io/parsers/readers.py", line 1407, in __init__
    self._engine = self._make_engine(f, self.engine)
  File "/home/airflow/.local/lib/python3.8/site-packages/pandas/io/parsers/readers.py", line 1679, in _make_engine
    return mapping[engine](f, **self.options)
  File "/home/airflow/.local/lib/python3.8/site-packages/pandas/io/parsers/c_parser_wrapper.py", line 93, in __init__
    self._reader = parsers.TextReader(src, **kwds)
  File "pandas/_libs/parsers.pyx", line 557, in pandas._libs.parsers.TextReader.__cinit__
pandas.errors.EmptyDataError: No columns to parse from file
[2025-10-23T16:59:12.188+0000] {taskinstance.py:1400} INFO - Marking task as FAILED. dag_id=ckan_data_etl, task_id=load, execution_date=20241005T000000, start_date=20251023T165911, end_date=20251023T165912
[2025-10-23T16:59:12.214+0000] {standard_task_runner.py:104} ERROR - Failed to execute job 678 for task load (No columns to parse from file; 863)
[2025-10-23T16:59:12.276+0000] {local_task_job_runner.py:228} INFO - Task exited with return code 1
[2025-10-23T16:59:12.313+0000] {taskinstance.py:2778} INFO - 0 downstream tasks scheduled from follow-on schedule check
